Workbook

Sheet Model v1.19.31
B2: This overview will not be maintained with the new fields, but it is kept for its overview value
B3: Design Table (DE) | F3: Sampling Details (SD) | J3: Vessel Selection (VS) | N3: Fishing Trip (FT) | R3: Fishing Operation (FO) | V3: Species Selection (SS) | Z3: Sample (SA) | AD3: Frequency Measure (FM) | AH3: Biological Variable (BV)
A4: =IF(ISBLANK(Design!A2)=TRUE, Design!B2, "") | B4: =IF(ISBLANK(Design!A2)=TRUE, Design!F2, "") | C4: =IF(ISBLANK(Design!A2)=TRUE, Design!M2, "") | E4: =IF(ISBLANK('Sampling Details'!A2)=TRUE, 'Sampling Details'!B2, "") | F4: =IF(ISBLANK('Sampling Details'!A2)=TRUE, 'Sampling Details'!F2, "") | G4: =IF(ISBLANK('Sampling Details'!A2)=TRUE, 'Sampling Details'!M2, "") | I4: =IF(ISBLANK('Vessel Selection'!A2)=TRUE, 'Vessel Selection'!B2, "") | J4: =IF(ISBLANK('Vessel Selection'!A2)=TRUE, 'Vessel Selection'!F2, "") | K4: =IF(ISBLANK('Vessel Selection'!A2)=TRUE, 'Vessel Selection'!M2, "") | N4: =IF(ISBLANK('Fishing Trip'!A2)=TRUE, 'Fishing Trip'!F2, "") | O4: =IF(ISBLANK('Fishing Trip'!A2)=TRUE, 'Fishing Trip'!M2, "") | Q4: =IF(ISBLANK('Fishing Operation'!A2)=TRUE, 'Fishing Operation'!B2, "") | R4: =IF(ISBLANK('Fishing Operation'!A2)=TRUE, 'Fishing Operation'!F2, "") | S4: =IF(ISBLANK('Fishing Operation'!A2)=TRUE, 'Fishing Operation'!M2, "") | U4: =IF(ISBLANK('Species Selection'!A2)=TRUE, 'Species Selection'!B2, "") | V4: =IF(ISBLANK('Species Selection'!A2)=TRUE,'Species Selection'!F2, "") | W4: =IF(ISBLANK('Species Selection'!A2)=TRUE,'Species Selection'!M2, "") | Y4: =IF(ISBLANK(Sample!A2)=TRUE, Sample!B2, "") | Z4: =IF(ISBLANK(Sample!A2)=TRUE, Sample!F2, "") | AA4: =IF(ISBLANK(Sample!A2)=TRUE, Sample!M2, "") | AC4: =IF(ISBLANK('Frequency Measure'!A2)=TRUE, 'Frequency Measure'!B2, "") | AD4: =IF(ISBLANK('Frequency Measure'!A2)=TRUE, 'Frequency Measure'!F2, "") | AE4: =IF(ISBLANK('Frequency Measure'!A2)=TRUE, 'Frequency Measure'!M2, "") | AG4: =IF(ISBLANK('Biological Variable'!A2)=TRUE, 'Biological Variable'!B2, "") | AH4: =IF(ISBLANK('Biological Variable'!A2)=TRUE, 'Biological Variable'!F2, "") | AI4: =IF(ISBLANK('Biological Variable'!A2)=TRUE, 'Biological Variable'!M2, "")
A5: =IF(ISBLANK(Design!A3)=TRUE, Design!B3, "") -> 0 | B5: =IF(ISBLANK(Design!A3)=TRUE, Design!F3, "") -> DErecordType | C5: =IF(ISBLANK(Design!A3)=TRUE, Design!M3, "") -> Fixed value ('DE') | E5: =IF(ISBLANK('Sampling Details'!A3)=TRUE, 'Sampling Details'!B3, "") | F5: =IF(ISBLANK('Sampling Details'!A3)=TRUE, 'Sampling Details'!F3, "") | G5: =IF(ISBLANK('Sampling Details'!A3)=TRUE, 'Sampling Details'!M3, "") | I5: =IF(ISBLANK('Vessel Selection'!A3)=TRUE, 'Vessel Selection'!B3, "") | J5: =IF(ISBLANK('Vessel Selection'!A3)=TRUE, 'Vessel Selection'!F3, "") | K5: =IF(ISBLANK('Vessel Selection'!A3)=TRUE, 'Vessel Selection'!M3, "") | N5: =IF(ISBLANK('Fishing Trip'!A3)=TRUE, 'Fishing Trip'!F3, "") | O5: =IF(ISBLANK('Fishing Trip'!A3)=TRUE, 'Fishing Trip'!M3, "") | Q5: =IF(ISBLANK('Fishing Operation'!A3)=TRUE, 'Fishing Operation'!B3, "") | R5: =IF(ISBLANK('Fishing Operation'!A3)=TRUE, 'Fishing Operation'!F3, "") | S5: =IF(ISBLANK('Fishing Operation'!A3)=TRUE, 'Fishing Operation'!M3, "") | U5: =IF(ISBLANK('Species Selection'!A3)=TRUE, 'Species Selection'!B3, "") | V5: =IF(ISBLANK('Species Selection'!A3)=TRUE,'Species Selection'!F3, "") | W5: =IF(ISBLANK('Species Selection'!A3)=TRUE,'Species Selection'!M3, "") | Y5: =IF(ISBLANK(Sample!#REF!)=TRUE, Sample!#REF!, "") | Z5: =IF(ISBLANK(Sample!#REF!)=TRUE, Sample!#REF!, "") | AA5: =IF(ISBLANK(Sample!#REF!)=TRUE, Sample!#REF!, "") | AC5: =IF(ISBLANK('Frequency Measure'!A3)=TRUE, 'Frequency Measure'!B3, "") | AD5: =IF(ISBLANK('Frequency Measure'!A3)=TRUE, 'Frequency Measure'!F3, "") | AE5: =IF(ISBLANK('Frequency Measure'!A3)=TRUE, 'Frequency Measure'!M3, "") | AG5: =IF(ISBLANK('Biological Variable'!A3)=TRUE, 'Biological Variable'!B3, "") | AH5: =IF(ISBLANK('Biological Variable'!A3)=TRUE, 'Biological Variable'!F3, "") | AI5: =IF(ISBLANK('Biological Variable'!A3)=TRUE, 'Biological Variable'!M3, "")
A6: =IF(ISBLANK(Design!A4)=TRUE, Design!B4, "") -> 0 | B6: =IF(ISBLANK(Design!A4)=TRUE, Design!F4, "") -> DEsamplingScheme | C6: =IF(ISBLANK(Design!A4)=TRUE, Design!M4, "") -> Sampling Scheme Name | E6: =IF(ISBLANK('Sampling Details'!A4)=TRUE, 'Sampling Details'!B4, "") -> 0 | F6: =IF(ISBLANK('Sampling Details'!A4)=TRUE, 'Sampling Details'!F4, "") -> SDrecordType | G6: =IF(ISBLANK('Sampling Details'!A4)=TRUE, 'Sampling Details'!M4, "") -> Fixed value ('SD') | I6: =IF(ISBLANK('Vessel Selection'!A4)=TRUE, 'Vessel Selection'!B4, "") | J6: =IF(ISBLANK('Vessel Selection'!A4)=TRUE, 'Vessel Selection'!F4, "") | K6: =IF(ISBLANK('Vessel Selection'!A4)=TRUE, 'Vessel Selection'!M4, "") | N6: =IF(ISBLANK('Fishing Trip'!A4)=TRUE, 'Fishing Trip'!F4, "") | O6: =IF(ISBLANK('Fishing Trip'!A4)=TRUE, 'Fishing Trip'!M4, "") | Q6: =IF(ISBLANK('Fishing Operation'!A5)=TRUE, 'Fishing Operation'!B5, "") -> 0 | R6: =IF(ISBLANK('Fishing Operation'!A4)=TRUE, 'Fishing Operation'!F4, "") | S6: =IF(ISBLANK('Fishing Operation'!A4)=TRUE, 'Fishing Operation'!M4, "") | U6: =IF(ISBLANK('Species Selection'!A7)=TRUE, 'Species Selection'!B7, "") | V6: =IF(ISBLANK('Species Selection'!A7)=TRUE,'Species Selection'!F7, "") | W6: =IF(ISBLANK('Species Selection'!A7)=TRUE,'Species Selection'!M7, "") | Y6: =IF(ISBLANK(Sample!A3)=TRUE, Sample!B3, "") | Z6: =IF(ISBLANK(Sample!A3)=TRUE, Sample!F3, "") | AA6: =IF(ISBLANK(Sample!A3)=TRUE, Sample!M3, "") | AC6: =IF(ISBLANK('Frequency Measure'!A4)=TRUE, 'Frequency Measure'!B4, "") -> 0 | AD6: =IF(ISBLANK('Frequency Measure'!A4)=TRUE, 'Frequency Measure'!F4, "") -> FMrecordType | AE6: =IF(ISBLANK('Frequency Measure'!A4)=TRUE, 'Frequency Measure'!M4, "") -> Fixed value ('FM') | AG6: =IF(ISBLANK('Biological Variable'!A4)=TRUE, 'Biological Variable'!B4, "") | AH6: =IF(ISBLANK('Biological Variable'!A4)=TRUE, 'Biological Variable'!F4, "") | AI6: =IF(ISBLANK('Biological Variable'!A4)=TRUE, 'Biological Variable'!M4, "")
A7: =IF(ISBLANK(Design!A6)=TRUE, Design!B6, "") -> 0 | B7: =IF(ISBLANK(Design!A5)=TRUE, Design!F5, "") -> DEsamplingSchemeType | C7: =IF(ISBLANK(Design!A5)=TRUE, Design!M5, "") -> Sampling scheme type code list: 'Regional Routine', 'Regional Pilot', 'National Routine', 'National Pilot'. | E7: =IF(ISBLANK('Sampling Details'!A5)=TRUE, 'Sampling Details'!B5, "") -> 0 | F7: =IF(ISBLANK('Sampling Details'!A5)=TRUE, 'Sampling Details'!F5, "") -> SDcountry | G7: =IF(ISBLANK('Sampling Details'!A5)=TRUE, 'Sampling Details'!M5, "") -> Sampling Country | I7: =IF(ISBLANK('Vessel Selection'!A5)=TRUE, 'Vessel Selection'!B5, "") | J7: =IF(ISBLANK('Vessel Selection'!A5)=TRUE, 'Vessel Selection'!F5, "") | K7: =IF(ISBLANK('Vessel Selection'!A5)=TRUE, 'Vessel Selection'!M5, "") | N7: =IF(ISBLANK('Fishing Trip'!A5)=TRUE, 'Fishing Trip'!F5, "") | O7: =IF(ISBLANK('Fishing Trip'!A5)=TRUE, 'Fishing Trip'!M5, "") | Q7: =IF(ISBLANK('Fishing Operation'!#REF!)=TRUE, 'Fishing Operation'!#REF!, "") | R7: =IF(ISBLANK('Fishing Operation'!A5)=TRUE, 'Fishing Operation'!F5, "") -> FOrecordType | S7: =IF(ISBLANK('Fishing Operation'!A5)=TRUE, 'Fishing Operation'!M5, "") -> Fixed value ('FO') | U7: =IF(ISBLANK('Species Selection'!A9)=TRUE, 'Species Selection'!B9, "") -> 0 | V7: =IF(ISBLANK('Species Selection'!A8)=TRUE,'Species Selection'!F8, "") | W7: =IF(ISBLANK('Species Selection'!A8)=TRUE,'Species Selection'!M8, "") | Y7: =IF(ISBLANK(Sample!A4)=TRUE, Sample!B4, "") -> 0 | Z7: =IF(ISBLANK(Sample!A4)=TRUE, Sample!F4, "") -> SArecordType | AA7: =IF(ISBLANK(Sample!A4)=TRUE, Sample!M4, "") -> Fixed value ('SA') | AC7: =IF(ISBLANK('Frequency Measure'!A7)=TRUE, 'Frequency Measure'!B7, "") -> 0 | AD7: =IF(ISBLANK('Frequency Measure'!A7)=TRUE, 'Frequency Measure'!F7, "") -> FMclassMeasured | AE7: =IF(ISBLANK('Frequency Measure'!A7)=TRUE, 'Frequency Measure'!M7, "") -> The length in mm or weight in g with no decimal. | AG7: =IF(ISBLANK('Biological Variable'!A5)=TRUE, 'Biological Variable'!B5, "") -> 0 | AH7: =IF(ISBLANK('Biological Variable'!A5)=TRUE, 'Biological Variable'!F5, "") -> BVrecordType | AI7: =IF(ISBLANK('Biological Variable'!A5)=TRUE, 'Biological Variable'!M5, "") -> Fixed value ('BV')
A8: =IF(ISBLANK(Design!A7)=TRUE, Design!B7, "") -> 0 | B8: =IF(ISBLANK(Design!A6)=TRUE, Design!F6, "") -> DEyear | C8: =IF(ISBLANK(Design!A6)=TRUE, Design!M6, "") -> Year of sampling | E8: =IF(ISBLANK('Sampling Details'!A6)=TRUE, 'Sampling Details'!B6, "") -> 0 | F8: =IF(ISBLANK('Sampling Details'!A6)=TRUE, 'Sampling Details'!F6, "") -> SDinstitution | G8: =IF(ISBLANK('Sampling Details'!A6)=TRUE, 'Sampling Details'!M6, "") -> Sampling Institute | I8: =IF(ISBLANK('Vessel Selection'!A6)=TRUE, 'Vessel Selection'!B6, "") -> 0 | J8: =IF(ISBLANK('Vessel Selection'!A6)=TRUE, 'Vessel Selection'!F6, "") -> VSrecordType | K8: =IF(ISBLANK('Vessel Selection'!A6)=TRUE, 'Vessel Selection'!M6, "") -> Fixed value ('VS') | N8: =IF(ISBLANK('Fishing Trip'!A6)=TRUE, 'Fishing Trip'!F6, "") | O8: =IF(ISBLANK('Fishing Trip'!A6)=TRUE, 'Fishing Trip'!M6, "") | Q8: =IF(ISBLANK('Fishing Operation'!A8)=TRUE, 'Fishing Operation'!B8, "") -> 0 | R8: =IF(ISBLANK('Fishing Operation'!A6)=TRUE, 'Fishing Operation'!F6, "") -> FOstratification | S8: =IF(ISBLANK('Fishing Operation'!A6)=TRUE, 'Fishing Operation'!M6, "") -> Indicator of presence ("Y") or absence ("N") of stratification of units in that level of the sampling hierarchy | U8: =IF(ISBLANK('Species Selection'!A11)=TRUE, 'Species Selection'!B11, "") -> 0 | V8: =IF(ISBLANK('Species Selection'!A9)=TRUE,'Species Selection'!F9, "") -> SSrecordType | W8: =IF(ISBLANK('Species Selection'!A9)=TRUE,'Species Selection'!M9, "") -> Fixed value ('SS') | Y8: =IF(ISBLANK(Sample!#REF!)=TRUE, Sample!#REF!, "") | Z8: =IF(ISBLANK(Sample!#REF!)=TRUE, Sample!#REF!, "") | AA8: =IF(ISBLANK(Sample!#REF!)=TRUE, Sample!#REF!, "") | AC8: =IF(ISBLANK('Frequency Measure'!A8)=TRUE, 'Frequency Measure'!B8, "") -> 0 | AD8: =IF(ISBLANK('Frequency Measure'!A8)=TRUE, 'Frequency Measure'!F8, "") -> FMnumberAtUnit | AE8: =IF(ISBLANK('Frequency Measure'!A8)=TRUE, 'Frequency Measure'!M8, "") -> Number of individuals. | AG8: =IF(ISBLANK('Biological Variable'!A6)=TRUE, 'Biological Variable'!B6, "") -> 0 | AH8: =IF(ISBLANK('Biological Variable'!A6)=TRUE, 'Biological Variable'!F6, "") -> BVnationalUniqueFishId | AI8: =IF(ISBLANK('Biological Variable'!A6)=TRUE, 'Biological Variable'!M6, "") -> National numbering system of the individual fish.
A9: =IF(ISBLANK(Design!A9)=TRUE, Design!B9, "") -> 0 | B9: =IF(ISBLANK(Design!A7)=TRUE, Design!F7, "") -> DEstratumName | C9: =IF(ISBLANK(Design!A7)=TRUE, Design!M7, "") -> Sampling frame stratum. | E9: =IF(ISBLANK('Sampling Details'!A7)=TRUE, 'Sampling Details'!B7, "") -> 0 | F9: =IF(ISBLANK('Sampling Details'!A7)=TRUE, 'Sampling Details'!F7, "") -> 0 | G9: =IF(ISBLANK('Sampling Details'!A7)=TRUE, 'Sampling Details'!M7, "") -> 0 | I9: =IF(ISBLANK('Vessel Selection'!A10)=TRUE, 'Vessel Selection'!B10, "") -> 0 | J9: =IF(ISBLANK('Vessel Selection'!A8)=TRUE, 'Vessel Selection'!F8, "") -> VSencryptedVesselCode | K9: =IF(ISBLANK('Vessel Selection'!A8)=TRUE, 'Vessel Selection'!M8, "") -> Encrypted by the national institute before it is upload. This code it refering to the Encrypted Vessel Identifier field in the Vessel Details. | N9: =IF(ISBLANK('Fishing Trip'!A7)=TRUE, 'Fishing Trip'!F7, "") | O9: =IF(ISBLANK('Fishing Trip'!A7)=TRUE, 'Fishing Trip'!M7, "") | Q9: =IF(ISBLANK('Fishing Operation'!A12)=TRUE, 'Fishing Operation'!B12, "") -> 0 | R9: =IF(ISBLANK('Fishing Operation'!#REF!)=TRUE, 'Fishing Operation'!#REF!, "") | S9: =IF(ISBLANK('Fishing Operation'!#REF!)=TRUE, 'Fishing Operation'!#REF!, "") | U9: =IF(ISBLANK('Species Selection'!A16)=TRUE, 'Species Selection'!B16, "") -> 0 | V9: =IF(ISBLANK('Species Selection'!A11)=TRUE,'Species Selection'!F11, "") -> SSstratification | W9: =IF(ISBLANK('Species Selection'!A11)=TRUE,'Species Selection'!M11, "") -> Indicator of presence ("Y") or absence ("N") of stratification of units in that level of the sampling hierarchy | Y9: =IF(ISBLANK(Sample!A8)=TRUE, Sample!B8, "") -> 0 | Z9: =IF(ISBLANK(Sample!A8)=TRUE, Sample!F8, "") -> SAstratumName | AA9: =IF(ISBLANK(Sample!A8)=TRUE, Sample!M8, "") -> The stratum of this sample, 'U' if unstratified | AC9: =IF(ISBLANK('Frequency Measure'!A9)=TRUE, 'Frequency Measure'!B9, "") -> 0 | AD9: =IF(ISBLANK('Frequency Measure'!A9)=TRUE, 'Frequency Measure'!F9, "") -> FMtypeMeasured | AE9: =IF(ISBLANK('Frequency Measure'!A9)=TRUE, 'Frequency Measure'!M9, "") -> The measurement type of the class. | AG9: =IF(ISBLANK('Biological Variable'!A10)=TRUE, 'Biological Variable'!B10, "") -> 0 | AH9: =IF(ISBLANK('Biological Variable'!A10)=TRUE, 'Biological Variable'!F10, "") -> BVstratumName | AI9: =IF(ISBLANK('Biological Variable'!A10)=TRUE, 'Biological Variable'!M10, "") -> The stratum of this record, 'U' if unstratified
A10: =IF(ISBLANK(Design!A10)=TRUE, Design!B10, "") -> 0 | B10: =IF(ISBLANK(Design!A8)=TRUE, Design!F8, "") -> DEhierarchyCorrect | C10: =IF(ISBLANK(Design!A8)=TRUE, Design!M8, "") -> Was the hierarchy clearly identified? | E10: =IF(ISBLANK('Sampling Details'!A8)=TRUE, 'Sampling Details'!B8, "") -> 0 | F10: =IF(ISBLANK('Sampling Details'!A8)=TRUE, 'Sampling Details'!G8, "") -> 0 | G10: =IF(ISBLANK('Sampling Details'!A8)=TRUE, 'Sampling Details'!M8, "") -> 0 | I10: =IF(ISBLANK('Vessel Selection'!A14)=TRUE, 'Vessel Selection'!B14, "") -> 0 | J10: =IF(ISBLANK('Vessel Selection'!A9)=TRUE, 'Vessel Selection'!F9, "") -> VSstratification | K10: =IF(ISBLANK('Vessel Selection'!A9)=TRUE, 'Vessel Selection'!M9, "") -> Indicator of presence ("Y") or absence ("N") of stratification of units in that level of the sampling hierarchy | N10: =IF(ISBLANK('Fishing Trip'!A8)=TRUE, 'Fishing Trip'!F8, "") | O10: =IF(ISBLANK('Fishing Trip'!A8)=TRUE, 'Fishing Trip'!M8, "") | Q10: =IF(ISBLANK('Fishing Operation'!A13)=TRUE, 'Fishing Operation'!B13, "") -> 0 | R10: =IF(ISBLANK('Fishing Operation'!A8)=TRUE, 'Fishing Operation'!F8, "") -> FOstratumName | S10: =IF(ISBLANK('Fishing Operation'!A8)=TRUE, 'Fishing Operation'!M8, "") -> Name of stratum ('U' for unstratified) | U10: =IF(ISBLANK('Species Selection'!A12)=TRUE, 'Species Selection'!B12, "") -> 0 | V10: =IF(ISBLANK('Species Selection'!A16)=TRUE,'Species Selection'!F16, "") -> SScatchFraction | W10: =IF(ISBLANK('Species Selection'!A16)=TRUE,'Species Selection'!M16, "") -> Registers how the catch is sampled by observers. This is really a strata so e.g., ”catch” and ”lan” cannot be provided for the same haul. Population is given by catchReg in upper table | Y10: =IF(ISBLANK(Sample!#REF!)=TRUE, Sample!#REF!, "") | Z10: =IF(ISBLANK(Sample!A9)=TRUE, Sample!F9, "") -> SAspeciesCode | AA10: =IF(ISBLANK(Sample!A9)=TRUE, Sample!M9, "") -> The Aphiaid code of the specie | AC10: =IF(ISBLANK('Frequency Measure'!A12)=TRUE, 'Frequency Measure'!B12, "") -> 0 | AD10: =IF(ISBLANK('Frequency Measure'!A12)=TRUE, 'Frequency Measure'!F12, "") -> FMaccuracy | AE10: =IF(ISBLANK('Frequency Measure'!A12)=TRUE, 'Frequency Measure'!M12, "") -> Accuracy e.g. "cm" | AG10: =IF(ISBLANK('Biological Variable'!A11)=TRUE, 'Biological Variable'!B11, "") -> 0 | AH10: =IF(ISBLANK('Biological Variable'!A11)=TRUE, 'Biological Variable'!F11, "") -> BVtypeMeasured | AI10: =IF(ISBLANK('Biological Variable'!A11)=TRUE, 'Biological Variable'!M11, "") -> Type of measurment e.g. "Age"
A11: =IF(ISBLANK(Design!A12)=TRUE, Design!B12, "") -> 0 | B11: =IF(ISBLANK(Design!A9)=TRUE, Design!F9, "") -> DEhierarchy | C11: =IF(ISBLANK(Design!A9)=TRUE, Design!M9, "") -> Upper Hierarchy | I11: =IF(ISBLANK('Vessel Selection'!A15)=TRUE, 'Vessel Selection'!B15, "") -> 0 | J11: =IF(ISBLANK('Vessel Selection'!A10)=TRUE, 'Vessel Selection'!F10, "") -> VSstratumName | K11: =IF(ISBLANK('Vessel Selection'!A10)=TRUE, 'Vessel Selection'!M10, "") -> Name of stratum ('U' for unstratified). | N11: =IF(ISBLANK('Fishing Trip'!A9)=TRUE, 'Fishing Trip'!F9, "") -> FTrecordType | O11: =IF(ISBLANK('Fishing Trip'!A9)=TRUE, 'Fishing Trip'!M9, "") -> Fixed value ('FT') | Q11: =IF(ISBLANK('Fishing Operation'!A14)=TRUE, 'Fishing Operation'!B14, "") -> 0 | R11: =IF(ISBLANK('Fishing Operation'!A9)=TRUE, 'Fishing Operation'!F9, "") -> FOclustering | S11: =IF(ISBLANK('Fishing Operation'!A9)=TRUE, 'Fishing Operation'!M9, "") -> Indicator existence and type of cluster sampling of units in that level of the sampling hierarchy | U11: =IF(ISBLANK('Species Selection'!A19)=TRUE, 'Species Selection'!B19, "") -> 0 | V11: =IF(ISBLANK('Species Selection'!A17)=TRUE,'Species Selection'!F17, "") -> SSobservationType | W11: =IF(ISBLANK('Species Selection'!A17)=TRUE,'Species Selection'!M17, "") -> vol = volume, vis = visual. | Y11: =IF(ISBLANK(Sample!A9)=TRUE, Sample!B9, "") -> 0 | Z11: =IF(ISBLANK(Sample!A10)=TRUE, Sample!F10, "") -> SAspeciesCodeFAO | AA11: =IF(ISBLANK(Sample!A10)=TRUE, Sample!M10, "") -> The FAO species code | AC11: =IF(ISBLANK('Frequency Measure'!A7)=TRUE, 'Frequency Measure'!B7, "") -> 0 | AD11: =IF(ISBLANK('Frequency Measure'!A15)=TRUE, 'Frequency Measure'!F15, "") -> FMsampler | AE11: =IF(ISBLANK('Frequency Measure'!A15)=TRUE, 'Frequency Measure'!M15, "") -> Self-sampling, Observer, Control, Electronic Monitoring (EM). In the future potential combinations of e.g. observer and EM | AG11: =IF(ISBLANK('Biological Variable'!A12)=TRUE, 'Biological Variable'!B12, "") -> 0 | AH11: =IF(ISBLANK('Biological Variable'!A12)=TRUE, 'Biological Variable'!F12, "") -> BVvalueMeasured | AI11: =IF(ISBLANK('Biological Variable'!A12)=TRUE, 'Biological Variable'!M12, "") -> Measured value of the Biological variable.
B12: =IF(ISBLANK(Design!A10)=TRUE, Design!F10, "") -> DEsampled | C12: =IF(ISBLANK(Design!A10)=TRUE, Design!M10, "") -> 0 | I12: =IF(ISBLANK('Vessel Selection'!#REF!)=TRUE, 'Vessel Selection'!#REF!, "") | J12: =IF(ISBLANK('Vessel Selection'!A11)=TRUE, 'Vessel Selection'!F11, "") -> VSclustering | K12: =IF(ISBLANK('Vessel Selection'!A11)=TRUE, 'Vessel Selection'!M11, "") -> Indicator existence and type of cluster sampling of units in that level of the sampling hierarchy | N12: =IF(ISBLANK('Fishing Trip'!#REF!)=TRUE, 'Fishing Trip'!#REF!, "") | O12: =IF(ISBLANK('Fishing Trip'!#REF!)=TRUE, 'Fishing Trip'!#REF!, "") | Q12: =IF(ISBLANK('Fishing Operation'!A15)=TRUE, 'Fishing Operation'!B15, "") -> 0 | R12: =IF(ISBLANK('Fishing Operation'!A10)=TRUE, 'Fishing Operation'!F10, "") -> FOclusterName | S12: =IF(ISBLANK('Fishing Operation'!A10)=TRUE, 'Fishing Operation'!M10, "") -> Name or code of the cluster selected for sampling | U12: =IF(ISBLANK('Species Selection'!#REF!)=TRUE, 'Species Selection'!#REF!, "") | V12: =IF(ISBLANK('Species Selection'!A12)=TRUE,'Species Selection'!F12, "") -> SSstratumName | W12: =IF(ISBLANK('Species Selection'!A12)=TRUE,'Species Selection'!M12, "") -> Name of stratum ('U' for unstratified) | Y12: =IF(ISBLANK(Sample!#REF!)=TRUE, Sample!#REF!, "") | Z12: =IF(ISBLANK(Sample!A12)=TRUE, Sample!F12, "") -> SApresentation | AA12: =IF(ISBLANK(Sample!A12)=TRUE, Sample!M12, "") -> Presentation e.g. gutted, whole, headless etc. | AC12: =IF(ISBLANK('Frequency Measure'!#REF!)=TRUE, 'Frequency Measure'!#REF!, "") | AD12: =IF(ISBLANK('Frequency Measure'!A18)=TRUE, 'Frequency Measure'!F18, "") -> 0 | AE12: =IF(ISBLANK('Frequency Measure'!A18)=TRUE, 'Frequency Measure'!M18, "") -> 0 | AG12: =IF(ISBLANK('Biological Variable'!A13)=TRUE, 'Biological Variable'!B13, "") -> 0 | AH12: =IF(ISBLANK('Biological Variable'!A13)=TRUE, 'Biological Variable'!F13, "") -> BVvalueUnitOrScale | AI12: =IF(ISBLANK('Biological Variable'!A13)=TRUE, 'Biological Variable'!M13, "") -> The unit or scale of the measured value
I13: =IF(ISBLANK('Vessel Selection'!A18)=TRUE, 'Vessel Selection'!B18, "") -> 0 | J13: =IF(ISBLANK('Vessel Selection'!A12)=TRUE, 'Vessel Selection'!F12, "") -> VSclusterName | K13: =IF(ISBLANK('Vessel Selection'!A12)=TRUE, 'Vessel Selection'!M12, "") -> Name or code of the cluster selected for sampling | N13: =IF(ISBLANK('Fishing Trip'!A12)=TRUE, 'Fishing Trip'!F12, "") -> FTstratification | O13: =IF(ISBLANK('Fishing Trip'!A12)=TRUE, 'Fishing Trip'!M12, "") -> Indicator of presence ("Y") or absence ("N") of stratification of units in that level of the sampling hierarchy | Q13: =IF(ISBLANK('Fishing Operation'!A16)=TRUE, 'Fishing Operation'!B16, "") -> 0 | R13: =IF(ISBLANK('Fishing Operation'!A11)=TRUE, 'Fishing Operation'!F11, "") -> FOsampler | S13: =IF(ISBLANK('Fishing Operation'!A11)=TRUE, 'Fishing Operation'!M11, "") -> Self-sampling, Observer, Control, Electronic Monitoring (EM). In the future potential combinations of e.g. observer and EM | U13: =IF(ISBLANK('Species Selection'!A24)=TRUE, 'Species Selection'!B24, "") -> 0 | V13: =IF(ISBLANK('Species Selection'!A13)=TRUE,'Species Selection'!F13, "") -> SSclustering | W13: =IF(ISBLANK('Species Selection'!A13)=TRUE,'Species Selection'!M13, "") -> Indicator existence and type of cluster sampling of units in that level of the sampling hierarchy | Y13: =IF(ISBLANK(Sample!A12)=TRUE, Sample!B12, "") -> 0 | Z13: =IF(ISBLANK(Sample!A14)=TRUE, Sample!F14, "") -> SAcatchCategory | AA13: =IF(ISBLANK(Sample!A14)=TRUE, Sample!M14, "") -> Catch' = catch, 'Dis' = discard, 'Lan' = landing, 'BMS' = Below Minimum reference Size | AC13: =IF(ISBLANK('Frequency Measure'!A8)=TRUE, 'Frequency Measure'!B8, "") -> 0 | AD13: =IF(ISBLANK('Frequency Measure'!A19)=TRUE, 'Frequency Measure'!F19, "") -> 0 | AE13: =IF(ISBLANK('Frequency Measure'!A19)=TRUE, 'Frequency Measure'!M19, "") -> 0 | AG13: =IF(ISBLANK('Biological Variable'!#REF!)=TRUE, 'Biological Variable'!#REF!, "") | AH13: =IF(ISBLANK('Biological Variable'!#REF!)=TRUE, 'Biological Variable'!#REF!, "") | AI13: =IF(ISBLANK('Biological Variable'!#REF!)=TRUE, 'Biological Variable'!#REF!, "")
I14: =IF(ISBLANK('Vessel Selection'!#REF!)=TRUE, 'Vessel Selection'!#REF!, "") | J14: =IF(ISBLANK('Vessel Selection'!A13)=TRUE, 'Vessel Selection'!F13, "") -> VSsampler | K14: =IF(ISBLANK('Vessel Selection'!A13)=TRUE, 'Vessel Selection'!M13, "") -> Self-sampling, Observer, Control, Electronic Monitoring (EM). In the future potential combinations of e.g. observer and EM | N14: =IF(ISBLANK('Fishing Trip'!A13)=TRUE, 'Fishing Trip'!F13, "") -> FTstratumName | O14: =IF(ISBLANK('Fishing Trip'!A13)=TRUE, 'Fishing Trip'!M13, "") -> Name of stratum ('U' for unstratified) | Q14: =IF(ISBLANK('Fishing Operation'!A17)=TRUE, 'Fishing Operation'!B17, "") -> 0 | R14: =IF(ISBLANK('Fishing Operation'!A12)=TRUE, 'Fishing Operation'!F12, "") -> FOaggregationLevel | S14: =IF(ISBLANK('Fishing Operation'!A12)=TRUE, 'Fishing Operation'!M12, "") -> Aggrgation level (H=haul. T=trip) | U14: =IF(ISBLANK('Species Selection'!A26)=TRUE, 'Species Selection'!B26, "") -> 0 | V14: =IF(ISBLANK('Species Selection'!A14)=TRUE,'Species Selection'!F14, "") -> SSclusterName | W14: =IF(ISBLANK('Species Selection'!A14)=TRUE,'Species Selection'!M14, "") -> Name or code of the cluster selected for sampling | Y14: =IF(ISBLANK(Sample!A14)=TRUE, Sample!B14, "") -> 0 | Z14: =IF(ISBLANK(Sample!A15)=TRUE, Sample!F15, "") -> SAlandingCategory | AA14: =IF(ISBLANK(Sample!A15)=TRUE, Sample!M15, "") -> The intended usage at the time of landing. | AC14: =IF(ISBLANK('Frequency Measure'!A9)=TRUE, 'Frequency Measure'!B9, "") -> 0 | AG14: =IF(ISBLANK('Biological Variable'!#REF!)=TRUE, 'Biological Variable'!#REF!, "") | AH14: =IF(ISBLANK('Biological Variable'!#REF!)=TRUE, 'Biological Variable'!#REF!, "") | AI14: =IF(ISBLANK('Biological Variable'!#REF!)=TRUE, 'Biological Variable'!#REF!, "")
I15: =IF(ISBLANK('Vessel Selection'!#REF!)=TRUE, 'Vessel Selection'!#REF!, "") | J15: =IF(ISBLANK('Vessel Selection'!A14)=TRUE, 'Vessel Selection'!F14, "") -> VSnumberTotal | K15: =IF(ISBLANK('Vessel Selection'!A14)=TRUE, 'Vessel Selection'!M14, "") -> Total number of unique vessels in this stratum/cluster. | N15: =IF(ISBLANK('Fishing Trip'!A14)=TRUE, 'Fishing Trip'!F14, "") -> FTclustering | O15: =IF(ISBLANK('Fishing Trip'!A14)=TRUE, 'Fishing Trip'!M14, "") -> Indicator existence and type of cluster sampling of units in that level of the sampling hierarchy | Q15: =IF(ISBLANK('Fishing Operation'!A18)=TRUE, 'Fishing Operation'!B18, "") -> 0 | R15: =IF(ISBLANK('Fishing Operation'!A13)=TRUE, 'Fishing Operation'!F13, "") -> FOvalidity | S15: =IF(ISBLANK('Fishing Operation'!A13)=TRUE, 'Fishing Operation'!M13, "") -> Haul validity | U15: =IF(ISBLANK('Species Selection'!A29)=TRUE, 'Species Selection'!B29, "") -> 0 | V15: =IF(ISBLANK('Species Selection'!A18)=TRUE,'Species Selection'!F18, "") -> SSsampler | W15: =IF(ISBLANK('Species Selection'!A18)=TRUE,'Species Selection'!M18, "") -> Self-sampling, Observer, Control, Electronic Monitoring (EM). In the future potential combinations of e.g. observer and EM | Y15: =IF(ISBLANK(Sample!A15)=TRUE, Sample!B15, "") -> 0 | Z15: =IF(ISBLANK(Sample!A16)=TRUE, Sample!F16, "") -> SAcommSizeCatScale | AA15: =IF(ISBLANK(Sample!A16)=TRUE, Sample!M16, "") -> Commercial sorting scale code | AC15: =IF(ISBLANK('Frequency Measure'!A12)=TRUE, 'Frequency Measure'!B12, "") -> 0 | AG15: =IF(ISBLANK('Biological Variable'!A21)=TRUE, 'Biological Variable'!B21, "") -> 0 | AH15: =IF(ISBLANK('Biological Variable'!A21)=TRUE, 'Biological Variable'!F21, "") -> BVnumberTotal | AI15: =IF(ISBLANK('Biological Variable'!A21)=TRUE, 'Biological Variable'!M21, "") -> Total number of fish in this stratum
J16: =IF(ISBLANK('Vessel Selection'!A15)=TRUE, 'Vessel Selection'!F15, "") -> VSnumberSampled | K16: =IF(ISBLANK('Vessel Selection'!A15)=TRUE, 'Vessel Selection'!M15, "") -> The number of times vessels was sampled in this stratum/cluster (not necessarily unique vessels, the same vessel could be sampled multiple times) . If 3 samples was made and one vessel was selected twice, the number of vessels sampled is 3. | N16: =IF(ISBLANK('Fishing Trip'!A15)=TRUE, 'Fishing Trip'!F15, "") -> FTclusterName | O16: =IF(ISBLANK('Fishing Trip'!A15)=TRUE, 'Fishing Trip'!M15, "") -> Name or code of the cluster selected for sampling | Q16: =IF(ISBLANK('Fishing Operation'!A19)=TRUE, 'Fishing Operation'!B19, "") -> 0 | R16: =IF(ISBLANK('Fishing Operation'!A14)=TRUE, 'Fishing Operation'!F14, "") -> FOcatchReg | S16: =IF(ISBLANK('Fishing Operation'!A14)=TRUE, 'Fishing Operation'!M14, "") -> Registers what components of catch are expected in the species selection table options | V16: =IF(ISBLANK('Species Selection'!A19)=TRUE,'Species Selection'!F19, "") -> SSspeciesListName | W16: =IF(ISBLANK('Species Selection'!A19)=TRUE,'Species Selection'!M19, "") -> National name of the species list | Y16: =IF(ISBLANK(Sample!A16)=TRUE, Sample!B16, "") -> 0 | Z16: =IF(ISBLANK(Sample!A17)=TRUE, Sample!F17, "") -> SAcommSizeCat | AA16: =IF(ISBLANK(Sample!A17)=TRUE, Sample!M17, "") -> Commercial sorting category | AC16: =IF(ISBLANK('Frequency Measure'!#REF!)=TRUE, 'Frequency Measure'!#REF!, "") | AG16: =IF(ISBLANK('Biological Variable'!A22)=TRUE, 'Biological Variable'!B22, "") -> 0 | AH16: =IF(ISBLANK('Biological Variable'!A22)=TRUE, 'Biological Variable'!F22, "") -> BVnumberSampled | AI16: =IF(ISBLANK('Biological Variable'!A22)=TRUE, 'Biological Variable'!M22, "") -> The number of fish measured in this stratum
I17: =IF(ISBLANK('Temporal Event'!A2)=TRUE, 'Temporal Event'!B2, "") | J17: =IF(ISBLANK('Vessel Selection'!#REF!)=TRUE, 'Vessel Selection'!#REF!, "") | K17: =IF(ISBLANK('Vessel Selection'!#REF!)=TRUE, 'Vessel Selection'!#REF!, "") | N17: =IF(ISBLANK('Fishing Trip'!A16)=TRUE, 'Fishing Trip'!F16, "") -> FTsampler | O17: =IF(ISBLANK('Fishing Trip'!A16)=TRUE, 'Fishing Trip'!M16, "") -> Self-sampling, Observer, Control, Electronic Monitoring (EM). In the future potential combinations of e.g. observer and EM | Q17: =IF(ISBLANK('Fishing Operation'!A23)=TRUE, 'Fishing Operation'!B23, "") -> 0 | R17: =IF(ISBLANK('Fishing Operation'!A15)=TRUE, 'Fishing Operation'!F15, "") -> FOstartDate | S17: =IF(ISBLANK('Fishing Operation'!A15)=TRUE, 'Fishing Operation'!M15, "") -> Date when of the gear start. "YYYY-MM-DD" (UTC). date of shooting (active) or last setting (passive) of the gear. | V17: =IF(ISBLANK('Species Selection'!A24)=TRUE,'Species Selection'!F24, "") -> SSnumberTotal | W17: =IF(ISBLANK('Species Selection'!A24)=TRUE,'Species Selection'!M24, "") -> Number of species from the list that are present in the strata*fraction | Y17: =IF(ISBLANK(Sample!A17)=TRUE, Sample!B17, "") -> 0 | Z17: =IF(ISBLANK(Sample!A18)=TRUE, Sample!F18, "") -> SAsex | AA17: =IF(ISBLANK(Sample!A18)=TRUE, Sample!M18, "") -> Sex | AC17: =IF(ISBLANK('Frequency Measure'!#REF!)=TRUE, 'Frequency Measure'!#REF!, "") | AG17: =IF(ISBLANK('Biological Variable'!#REF!)=TRUE, 'Biological Variable'!#REF!, "") | AH17: =IF(ISBLANK('Biological Variable'!#REF!)=TRUE, 'Biological Variable'!#REF!, "") | AI17: =IF(ISBLANK('Biological Variable'!#REF!)=TRUE, 'Biological Variable'!#REF!, "")
I18: =IF(ISBLANK('Temporal Event'!A3)=TRUE, 'Temporal Event'!B3, "") | J18: =IF(ISBLANK('Vessel Selection'!A18)=TRUE, 'Vessel Selection'!F18, "") -> VSselectionMethod | K18: =IF(ISBLANK('Vessel Selection'!A18)=TRUE, 'Vessel Selection'!M18, "") -> The method of selecting vessels for sampling | N18: =IF(ISBLANK('Fishing Trip'!A18)=TRUE, 'Fishing Trip'!F18, "") -> FTnumberOfHaulsOrSets | O18: =IF(ISBLANK('Fishing Trip'!A18)=TRUE, 'Fishing Trip'!M18, "") -> Number of hauls/sets taken during the trip. Mandatory when FTsampler == "Observer” and FTsamplingType == “at-sea”. | Q18: =IF(ISBLANK('Fishing Operation'!A24)=TRUE, 'Fishing Operation'!B24, "") -> 0 | R18: =IF(ISBLANK('Fishing Operation'!A16)=TRUE, 'Fishing Operation'!F16, "") -> FOstartTime | S18: =IF(ISBLANK('Fishing Operation'!A16)=TRUE, 'Fishing Operation'!M16, "") -> Time when of the gear start. "HH:MM"… in UTC. Time of shooting (active) or last setting (passive) of the gear- | V18: =IF(ISBLANK('Species Selection'!A26)=TRUE,'Species Selection'!F26, "") -> SSnumberSampled | W18: =IF(ISBLANK('Species Selection'!A26)=TRUE,'Species Selection'!M26, "") -> Number of species selected for sampling | Y18: =IF(ISBLANK(Sample!A18)=TRUE, Sample!B18, "") -> 0 | Z18: =IF(ISBLANK(Sample!A36)=TRUE, Sample!F36, "") -> SAunitType | AA18: =IF(ISBLANK(Sample!A36)=TRUE, Sample!M36, "") -> The type of sampling unit | AC18: =IF(ISBLANK('Frequency Measure'!#REF!)=TRUE, 'Frequency Measure'!#REF!, "") | AG18: =IF(ISBLANK('Biological Variable'!A25)=TRUE, 'Biological Variable'!B25, "") -> 0 | AH18: =IF(ISBLANK('Biological Variable'!A25)=TRUE, 'Biological Variable'!F25, "") -> BVselectionMethod | AI18: =IF(ISBLANK('Biological Variable'!A25)=TRUE, 'Biological Variable'!M25, "") -> The method of selecting fish
I19: =IF(ISBLANK('Temporal Event'!A9)=TRUE, 'Temporal Event'!B9, "") -> 0 | J19: =IF(ISBLANK('Vessel Selection'!A19)=TRUE, 'Vessel Selection'!F19, "") -> VSunitName | K19: =IF(ISBLANK('Vessel Selection'!A19)=TRUE, 'Vessel Selection'!M19, "") -> The unique name of this unit. Indicate a sampling unit may appear more than once. Can be national identfier for the vessel, frequently similary to the encrypted vessel identifyer. Do not use the real name of vessel or anything that can identify the vessel. e.g. "Vessel1", etc. | N19: =IF(ISBLANK('Fishing Trip'!A19)=TRUE, 'Fishing Trip'!F19, "") -> FTdepartureLocation | O19: =IF(ISBLANK('Fishing Trip'!A19)=TRUE, 'Fishing Trip'!M19, "") -> LOCODE of departure Location. Mandatory when FTsampler == "Observer” and FTsamplingType == “at-sea” | Q19: =IF(ISBLANK('Fishing Operation'!A25)=TRUE, 'Fishing Operation'!B25, "") -> 0 | R19: =IF(ISBLANK('Fishing Operation'!A17)=TRUE, 'Fishing Operation'!F17, "") -> FOendDate | S19: =IF(ISBLANK('Fishing Operation'!A17)=TRUE, 'Fishing Operation'!M17, "") -> Date when the fishing operation ends or catch is removed (e.g., if the gear remains in water). "YYYY-MM-DD" (UTC). If FOaggregationLevel == T, this coincides with arrivalDate of trip. | V19: =IF(ISBLANK('Species Selection'!A29)=TRUE,'Species Selection'!F29, "") -> SSselectionMethod | W19: =IF(ISBLANK('Species Selection'!A29)=TRUE,'Species Selection'!M29, "") -> The method of selecting species for sampling | Y19: =IF(ISBLANK(Sample!A36)=TRUE, Sample!B36, "") -> 0 | Z19: =IF(ISBLANK(Sample!A37)=TRUE, Sample!F37, "") -> SAtotalWeightLive | AA19: =IF(ISBLANK(Sample!A37)=TRUE, Sample!M37, "") -> Whole weight in grammes. | AC19: =IF(ISBLANK('Frequency Measure'!#REF!)=TRUE, 'Frequency Measure'!#REF!, "") | AG19: =IF(ISBLANK('Biological Variable'!A27)=TRUE, 'Biological Variable'!B27, "") -> 0 | AH19: =IF(ISBLANK('Biological Variable'!A27)=TRUE, 'Biological Variable'!F27, "") -> BVsampler | AI19: =IF(ISBLANK('Biological Variable'!A27)=TRUE, 'Biological Variable'!M27, "") -> Self-sampling, Observer, Control, Electronic Monitoring (EM). In the future potential combinations of e.g. observer and EM
I20: =IF(ISBLANK('Temporal Event'!A10)=TRUE, 'Temporal Event'!B10, "") -> 0 | J20: =IF(ISBLANK('Vessel Selection'!A20)=TRUE, 'Vessel Selection'!F20, "") -> VSselectionMethodCluster | K20: =IF(ISBLANK('Vessel Selection'!A20)=TRUE, 'Vessel Selection'!M20, "") -> The method of selecting clusters | N20: =IF(ISBLANK('Fishing Trip'!A20)=TRUE, 'Fishing Trip'!F20, "") -> FTdepartureDate | O20: =IF(ISBLANK('Fishing Trip'!A20)=TRUE, 'Fishing Trip'!M20, "") -> Departure date | Q20: =IF(ISBLANK('Fishing Operation'!A26)=TRUE, 'Fishing Operation'!B26, "") -> 0 | R20: =IF(ISBLANK('Fishing Operation'!A18)=TRUE, 'Fishing Operation'!F18, "") -> FOendTime | S20: =IF(ISBLANK('Fishing Operation'!A18)=TRUE, 'Fishing Operation'!M18, "") -> Time when the fishing operation ends or catch is removed (e.g., if the gear remains in water). "HH:MM"… in UTC. Mandatory when FTsampler == “Observer” and FTsamplingType == “at-sea”. | V20: =IF(ISBLANK('Species Selection'!A31)=TRUE,'Species Selection'!F31, "") -> SSselectionMethodCluster | W20: =IF(ISBLANK('Species Selection'!A31)=TRUE,'Species Selection'!M31, "") -> The method of selecting clusters | Y20: =IF(ISBLANK(Sample!A37)=TRUE, Sample!B37, "") -> 0 | Z20: =IF(ISBLANK(Sample!A38)=TRUE, Sample!F38, "") -> SAsampleWeightLive | AA20: =IF(ISBLANK(Sample!A38)=TRUE, Sample!M38, "") -> Whole weight in grammes of the sample. | AC20: =IF(ISBLANK('Frequency Measure'!#REF!)=TRUE, 'Frequency Measure'!#REF!, "") | AH20: =IF(ISBLANK('Biological Variable'!A28)=TRUE, 'Biological Variable'!F28, "") -> 0 | AI20: =IF(ISBLANK('Biological Variable'!A28)=TRUE, 'Biological Variable'!M28, "") -> 0
I21: =IF(ISBLANK('Temporal Event'!A14)=TRUE, 'Temporal Event'!B14, "") -> 0 | J21: =IF(ISBLANK('Vessel Selection'!A21)=TRUE, 'Vessel Selection'!F21, "") -> VSnumberTotalClusters | K21: =IF(ISBLANK('Vessel Selection'!A21)=TRUE, 'Vessel Selection'!M21, "") -> Total number of clusters in that level of the sampling hierarchy | N21: =IF(ISBLANK('Fishing Trip'!A21)=TRUE, 'Fishing Trip'!F21, "") -> FTdepartureTime | O21: =IF(ISBLANK('Fishing Trip'!A21)=TRUE, 'Fishing Trip'!M21, "") -> Departure time. Mandatory when FTsampler == "Observer” and FTsamplingType == “at-sea” | Q21: =IF(ISBLANK('Fishing Operation'!A27)=TRUE, 'Fishing Operation'!B27, "") -> 0 | R21: =IF(ISBLANK('Fishing Operation'!A19)=TRUE, 'Fishing Operation'!F19, "") -> FOduration | S21: =IF(ISBLANK('Fishing Operation'!A19)=TRUE, 'Fishing Operation'!M19, "") -> Time spent towing (active) or soaking (passive) in minutes . Mandatory when FTsampler == “Observer” and FTsamplingType == “at-sea”. | V21: =IF(ISBLANK('Species Selection'!A32)=TRUE,'Species Selection'!F32, "") -> SSnumberTotalClusters | W21: =IF(ISBLANK('Species Selection'!A32)=TRUE,'Species Selection'!M32, "") -> Total number of clusters in that level of the sampling hierarchy | Y21: =IF(ISBLANK(Sample!A38)=TRUE, Sample!B38, "") -> 0 | Z21: =IF(ISBLANK(Sample!A39)=TRUE, Sample!F39, "") -> SAnumberTotal | AA21: =IF(ISBLANK(Sample!A39)=TRUE, Sample!M39, "") -> Total number of units in this stratum | AC21: =IF(ISBLANK('Frequency Measure'!#REF!)=TRUE, 'Frequency Measure'!#REF!, "")
I22: =IF(ISBLANK('Temporal Event'!A15)=TRUE, 'Temporal Event'!B15, "") -> 0 | J22: =IF(ISBLANK('Vessel Selection'!A22)=TRUE, 'Vessel Selection'!F22, "") -> VSnumberSampledClusters | K22: =IF(ISBLANK('Vessel Selection'!A22)=TRUE, 'Vessel Selection'!M22, "") -> Total number of clusters sampled | N22: =IF(ISBLANK('Fishing Trip'!A22)=TRUE, 'Fishing Trip'!F22, "") -> FTarrivalLocation | O22: =IF(ISBLANK('Fishing Trip'!A22)=TRUE, 'Fishing Trip'!M22, "") -> LOCODE of arrival location | Q22: =IF(ISBLANK('Fishing Operation'!A28)=TRUE, 'Fishing Operation'!B28, "") -> 0 | R22: =IF(ISBLANK('Fishing Operation'!A23)=TRUE, 'Fishing Operation'!F23, "") -> FOstartLat | S22: =IF(ISBLANK('Fishing Operation'!A23)=TRUE, 'Fishing Operation'!M23, "") -> Shooting (start) position in decimal degrees of latitude. | V22: =IF(ISBLANK('Species Selection'!A33)=TRUE,'Species Selection'!F33, "") -> SSnumberSampledClusters | W22: =IF(ISBLANK('Species Selection'!A33)=TRUE,'Species Selection'!M33, "") -> Total number of clusters sampled | Y22: =IF(ISBLANK(Sample!A39)=TRUE, Sample!B39, "") -> 0 | Z22: =IF(ISBLANK(Sample!A40)=TRUE, Sample!F40, "") -> SAnumberSampled | AA22: =IF(ISBLANK(Sample!A40)=TRUE, Sample!M40, "") -> The number of units sampled in this stratum
I23: =IF(ISBLANK('Temporal Event'!#REF!)=TRUE, 'Temporal Event'!#REF!, "") | J23: =IF(ISBLANK('Vessel Selection'!#REF!)=TRUE, 'Vessel Selection'!#REF!, "") | K23: =IF(ISBLANK('Vessel Selection'!#REF!)=TRUE, 'Vessel Selection'!#REF!, "") | N23: =IF(ISBLANK('Fishing Trip'!A23)=TRUE, 'Fishing Trip'!F23, "") -> FTarrivalDate | O23: =IF(ISBLANK('Fishing Trip'!A23)=TRUE, 'Fishing Trip'!M23, "") -> Arrival Date | Q23: =IF(ISBLANK('Fishing Operation'!A29)=TRUE, 'Fishing Operation'!B29, "") -> 0 | R23: =IF(ISBLANK('Fishing Operation'!A24)=TRUE, 'Fishing Operation'!F24, "") -> FOstartLon | S23: =IF(ISBLANK('Fishing Operation'!A24)=TRUE, 'Fishing Operation'!M24, "") -> Shooting (start) position in decimal degrees of longitude. | V23: =IF(ISBLANK('Species Selection'!#REF!)=TRUE,'Species Selection'!#REF!, "") | W23: =IF(ISBLANK('Species Selection'!#REF!)=TRUE,'Species Selection'!#REF!, "") | Y23: =IF(ISBLANK(Sample!A40)=TRUE, Sample!B40, "") -> 0 | Z23: =IF(ISBLANK(Sample!#REF!)=TRUE, Sample!#REF!, "") | AA23: =IF(ISBLANK(Sample!#REF!)=TRUE, Sample!#REF!, "")
I24: =IF(ISBLANK('Temporal Event'!A18)=TRUE, 'Temporal Event'!B18, "") -> 0 | J24: =IF(ISBLANK('Vessel Selection'!A26)=TRUE, 'Vessel Selection'!F26, "") -> VSreasonNotSampled | K24: =IF(ISBLANK('Vessel Selection'!A26)=TRUE, 'Vessel Selection'!M26, "") -> Reason for not sampling | N24: =IF(ISBLANK('Fishing Trip'!A24)=TRUE, 'Fishing Trip'!F24, "") -> FTarrivalTime | O24: =IF(ISBLANK('Fishing Trip'!A24)=TRUE, 'Fishing Trip'!M24, "") -> Arrival time. Mandatory when FTsampler == "Observer” and FTsamplingType == “at-sea” | Q24: =IF(ISBLANK('Fishing Operation'!A32)=TRUE, 'Fishing Operation'!B32, "") -> 0 | R24: =IF(ISBLANK('Fishing Operation'!A25)=TRUE, 'Fishing Operation'!F25, "") -> FOstopLat | S24: =IF(ISBLANK('Fishing Operation'!A25)=TRUE, 'Fishing Operation'!M25, "") -> Hauling (stop) position in decimal degrees of latitude. | V24: =IF(ISBLANK('Species Selection'!A37)=TRUE,'Species Selection'!F37, "") -> SSreasonNotSampled | W24: =IF(ISBLANK('Species Selection'!A37)=TRUE,'Species Selection'!M37, "") -> Reason for not sampling | Y24: =IF(ISBLANK(Sample!#REF!)=TRUE, Sample!#REF!, "") | Z24: =IF(ISBLANK(Sample!A43)=TRUE, Sample!F43, "") -> SAselectionMethod | AA24: =IF(ISBLANK(Sample!A43)=TRUE, Sample!M43, "") -> The method of selecting units for sampling
I25: =IF(ISBLANK('Temporal Event'!#REF!)=TRUE, 'Temporal Event'!#REF!, "") | J25: =IF(ISBLANK('Vessel Selection'!A27)=TRUE, 'Vessel Selection'!F27, "") -> VSnonResponseCollected | K25: =IF(ISBLANK('Vessel Selection'!A27)=TRUE, 'Vessel Selection'!M27, "") -> Indicate whether non-responses were recorded at this sampling level. | N25: =IF(ISBLANK('Fishing Trip'!A26)=TRUE, 'Fishing Trip'!F26, "") -> FTnumberTotal | O25: =IF(ISBLANK('Fishing Trip'!A26)=TRUE, 'Fishing Trip'!M26, "") -> Total number of unique trips in the stratum/cluster. | Q25: =IF(ISBLANK('Fishing Operation'!#REF!)=TRUE, 'Fishing Operation'!#REF!, "") | R25: =IF(ISBLANK('Fishing Operation'!A26)=TRUE, 'Fishing Operation'!F26, "") -> FOstopLon | S25: =IF(ISBLANK('Fishing Operation'!A26)=TRUE, 'Fishing Operation'!M26, "") -> Hauling (stop) position in decimal degrees of longitude. | U25: =IF(ISBLANK(#REF!)=TRUE,#REF!, "") | V25: =IF(ISBLANK('Species Selection'!A38)=TRUE,'Species Selection'!F38, "") -> SSnonResponseCollected | W25: =IF(ISBLANK('Species Selection'!A38)=TRUE,'Species Selection'!M38, "") -> Indicate whether non-responses were recorded at this sampling level. | Y25: =IF(ISBLANK(Sample!A43)=TRUE, Sample!B43, "") -> 0 | Z25: =IF(ISBLANK(Sample!A45)=TRUE, Sample!F45, "") -> SAlowerHierarchy | AA25: =IF(ISBLANK(Sample!A45)=TRUE, Sample!M45, "") -> The Lower Hierarchy that will be used for this Sample/Subsample
N26: =IF(ISBLANK('Fishing Trip'!A27)=TRUE, 'Fishing Trip'!F27, "") -> FTnumberSampled | O26: =IF(ISBLANK('Fishing Trip'!A27)=TRUE, 'Fishing Trip'!M27, "") -> The number of trips sampled in this stratum/cluster. | Q26: =IF(ISBLANK('Fishing Operation'!A35)=TRUE, 'Fishing Operation'!B35, "") -> 0 | R26: =IF(ISBLANK('Fishing Operation'!A27)=TRUE, 'Fishing Operation'!F27, "") -> FOexclusiveEconomicZoneIndicator | S26: =IF(ISBLANK('Fishing Operation'!A27)=TRUE, 'Fishing Operation'!M27, "") -> Exclusive Economic Zone indicator. | U26: =IF(ISBLANK(#REF!)=TRUE,#REF!, "") | Y26: =IF(ISBLANK(Sample!A45)=TRUE, Sample!B45, "") -> 0 | Z26: =IF(ISBLANK(Sample!A46)=TRUE, Sample!F46, "") -> SAsampler | AA26: =IF(ISBLANK(Sample!A46)=TRUE, Sample!M46, "") -> Self-sampling, Observer, Control, Electronic Monitoring (EM). In the future potential combinations of e.g. observer and EM
J27: Temporal Event (TE) | N27: =IF(ISBLANK('Fishing Trip'!#REF!)=TRUE, 'Fishing Trip'!#REF!, "") | O27: =IF(ISBLANK('Fishing Trip'!#REF!)=TRUE, 'Fishing Trip'!#REF!, "") | Q27: =IF(ISBLANK('Fishing Operation'!A36)=TRUE, 'Fishing Operation'!B36, "") -> 0 | R27: =IF(ISBLANK('Fishing Operation'!A28)=TRUE, 'Fishing Operation'!F28, "") -> FOarea | S27: =IF(ISBLANK('Fishing Operation'!A28)=TRUE, 'Fishing Operation'!M28, "") -> Area level 3 in the DCR. | U27: =IF(ISBLANK(#REF!)=TRUE,#REF!, "") | Y27: =IF(ISBLANK(Sample!A46)=TRUE, Sample!B46, "") -> 0 | Z27: =IF(ISBLANK(Sample!A50)=TRUE, Sample!F50, "") -> SAreasonNotSampledFM | AA27: =IF(ISBLANK(Sample!A50)=TRUE, Sample!M50, "") -> Reason for not sampling freq
J28: =IF(ISBLANK('Temporal Event'!A2)=TRUE, 'Temporal Event'!F2, "") | K28: =IF(ISBLANK('Temporal Event'!A2)=TRUE, 'Temporal Event'!M2, "") | N28: =IF(ISBLANK('Fishing Trip'!A30)=TRUE, 'Fishing Trip'!F30, "") -> FTselectionMethod | O28: =IF(ISBLANK('Fishing Trip'!A30)=TRUE, 'Fishing Trip'!M30, "") -> The method of selecting fishing trips for sampling | Q28: =IF(ISBLANK('Fishing Operation'!A37)=TRUE, 'Fishing Operation'!B37, "") -> 0 | R28: =IF(ISBLANK('Fishing Operation'!A29)=TRUE, 'Fishing Operation'!F29, "") -> FOrectangle | S28: =IF(ISBLANK('Fishing Operation'!A29)=TRUE, 'Fishing Operation'!M29, "") -> Area level 5 in the DCR | U28: =IF(ISBLANK(#REF!)=TRUE,#REF!, "") | V28: Species List Details (SL) | Y28: =IF(ISBLANK(Sample!A50)=TRUE, Sample!B50, "") -> 0 | Z28: =IF(ISBLANK(Sample!A51)=TRUE, Sample!F51, "") -> SAreasonNotSampledBV | AA28: =IF(ISBLANK(Sample!A51)=TRUE, Sample!M51, "") -> Reason for not sampling biovar
J29: =IF(ISBLANK('Temporal Event'!A3)=TRUE, 'Temporal Event'!F3, "") | K29: =IF(ISBLANK('Temporal Event'!A3)=TRUE, 'Temporal Event'!M3, "") | N29: =IF(ISBLANK('Fishing Trip'!A32)=TRUE, 'Fishing Trip'!F32, "") -> FTselectionMethodCluster | O29: =IF(ISBLANK('Fishing Trip'!A32)=TRUE, 'Fishing Trip'!M32, "") -> The method of selecting clusters | Q29: =IF(ISBLANK('Fishing Operation'!A38)=TRUE, 'Fishing Operation'!B38, "") -> 0 | R29: =IF(ISBLANK('Fishing Operation'!A32)=TRUE, 'Fishing Operation'!F32, "") -> FOjurisdictionArea | S29: =IF(ISBLANK('Fishing Operation'!A32)=TRUE, 'Fishing Operation'!M32, "") -> Area belonging to a country or a part of an area among others used by Long Distance Fisheries. | U29: =IF(ISBLANK(#REF!)=TRUE,#REF!, "") | V29: =IF(ISBLANK(#REF!)=TRUE,#REF!, "") | W29: =IF(ISBLANK(#REF!)=TRUE,#REF!, "") | Y29: =IF(ISBLANK(Sample!A65)=TRUE, Sample!B51, "") -> 0 | Z29: =IF(ISBLANK(Sample!A52)=TRUE, Sample!F52, "") -> SAtotalWeightMeasured | AA29: =IF(ISBLANK(Sample!A52)=TRUE, Sample!M52, "") -> Whole weight in grammes.
I30: =IF(ISBLANK(Location!A2)=TRUE, Location!B2, "") | J30: =IF(ISBLANK('Temporal Event'!A4)=TRUE, 'Temporal Event'!F4, "") | K30: =IF(ISBLANK('Temporal Event'!A4)=TRUE, 'Temporal Event'!M4, "") | N30: =IF(ISBLANK('Fishing Trip'!A33)=TRUE, 'Fishing Trip'!F33, "") -> FTnumberTotalClusters | O30: =IF(ISBLANK('Fishing Trip'!A33)=TRUE, 'Fishing Trip'!M33, "") -> Total number of clusters in that level of the sampling hierarchy | Q30: =IF(ISBLANK('Fishing Operation'!A36)=TRUE, 'Fishing Operation'!B36, "") -> 0 | R30: =IF(ISBLANK('Fishing Operation'!#REF!)=TRUE, 'Fishing Operation'!#REF!, "") | S30: =IF(ISBLANK('Fishing Operation'!#REF!)=TRUE, 'Fishing Operation'!#REF!, "") | U30: =IF(ISBLANK(#REF!)=TRUE,#REF!, "") | V30: =IF(ISBLANK(#REF!)=TRUE,#REF!, "") | W30: =IF(ISBLANK(#REF!)=TRUE,#REF!, "") | Y30: =IF(ISBLANK(Sample!#REF!)=TRUE, Sample!B52, "") | Z30: =IF(ISBLANK(Sample!A54)=TRUE, Sample!F54, "") -> SAsampleWeightMeasured | AA30: =IF(ISBLANK(Sample!A54)=TRUE, Sample!M54, "") -> Whole weight in grammes of the sample.
I31: =IF(ISBLANK(Location!A3)=TRUE, Location!B3, "") | J31: =IF(ISBLANK('Temporal Event'!A5)=TRUE, 'Temporal Event'!F5, "") | K31: =IF(ISBLANK('Temporal Event'!A5)=TRUE, 'Temporal Event'!M5, "") | N31: =IF(ISBLANK('Fishing Trip'!A34)=TRUE, 'Fishing Trip'!F34, "") -> FTnumberSampledClusters | O31: =IF(ISBLANK('Fishing Trip'!A34)=TRUE, 'Fishing Trip'!M34, "") -> Total number of clusters sampled | Q31: =IF(ISBLANK('Fishing Operation'!#REF!)=TRUE, 'Fishing Operation'!#REF!, "") | R31: =IF(ISBLANK('Fishing Operation'!A35)=TRUE, 'Fishing Operation'!F35, "") -> FOfishingDepth | S31: =IF(ISBLANK('Fishing Operation'!A35)=TRUE, 'Fishing Operation'!M35, "") -> Mean depth of gear | U31: =IF(ISBLANK(#REF!)=TRUE,#REF!, "") | V31: =IF(ISBLANK(#REF!)=TRUE,#REF!, "") | W31: =IF(ISBLANK(#REF!)=TRUE,#REF!, "") | Y31: =IF(ISBLANK(Sample!A40)=TRUE, Sample!B40, "") -> 0 | Z31: =IF(ISBLANK(Sample!A55)=TRUE, Sample!F55, "") -> SAconversionFactorMeasLive | AA31: =IF(ISBLANK(Sample!A55)=TRUE, Sample!M55, "") -> Conversion factor between measured weight and live weight.
I32: =IF(ISBLANK(Location!A4)=TRUE, Location!B4, "") -> 0 | J32: =IF(ISBLANK('Temporal Event'!A6)=TRUE, 'Temporal Event'!F6, "") -> TErecordType | K32: =IF(ISBLANK('Temporal Event'!A6)=TRUE, 'Temporal Event'!M6, "") -> Fixed value ('TE') | N32: =IF(ISBLANK('Fishing Trip'!#REF!)=TRUE, 'Fishing Trip'!#REF!, "") | O32: =IF(ISBLANK('Fishing Trip'!#REF!)=TRUE, 'Fishing Trip'!#REF!, "") | Q32: =IF(ISBLANK('Fishing Operation'!A37)=TRUE, 'Fishing Operation'!B37, "") -> 0 | R32: =IF(ISBLANK('Fishing Operation'!A36)=TRUE, 'Fishing Operation'!F36, "") -> FOwaterDepth | S32: =IF(ISBLANK('Fishing Operation'!A36)=TRUE, 'Fishing Operation'!M36, "") -> Mean depth of location | U32: =IF(ISBLANK(#REF!)=TRUE,#REF!, "") | V32: =IF(ISBLANK(#REF!)=TRUE,#REF!, "") | W32: =IF(ISBLANK(#REF!)=TRUE,#REF!, "") | Y32: =IF(ISBLANK(Sample!#REF!)=TRUE, Sample!#REF!, "") | Z32: =IF(ISBLANK(Sample!A13)=TRUE, Sample!F13, "") -> SAspecimensState | AA32: =IF(ISBLANK(Sample!A13)=TRUE, Sample!M13, "") -> State of the specimens (e.g., dead, damaged, etc).
J33: =IF(ISBLANK('Temporal Event'!A8)=TRUE, 'Temporal Event'!F8, "") -> TEstratification | K33: =IF(ISBLANK('Temporal Event'!A8)=TRUE, 'Temporal Event'!M8, "") -> Indicator of presence (Y) or absence (N) of stratification of units in that level of the sampling hierarchy | N33: =IF(ISBLANK('Fishing Trip'!A38)=TRUE, 'Fishing Trip'!F38, "") -> FTreasonNotSampled | O33: =IF(ISBLANK('Fishing Trip'!A38)=TRUE, 'Fishing Trip'!M38, "") -> Reason for not sampling | R33: =IF(ISBLANK('Fishing Operation'!A37)=TRUE, 'Fishing Operation'!F37, "") -> FOnationalFishingActivity | S33: =IF(ISBLANK('Fishing Operation'!A37)=TRUE, 'Fishing Operation'!M37, "") -> Country specific national fishing activity | V33: =IF(ISBLANK(#REF!)=TRUE,#REF!, "") | W33: =IF(ISBLANK(#REF!)=TRUE,#REF!, "")
J34: =IF(ISBLANK('Temporal Event'!A9)=TRUE, 'Temporal Event'!F9, "") -> TEtimeUnit | K34: =IF(ISBLANK('Temporal Event'!A9)=TRUE, 'Temporal Event'!M9, "") -> The time unit e.g. "week" | N34: =IF(ISBLANK('Fishing Trip'!A37)=TRUE, 'Fishing Trip'!F37, "") -> FTsampled | O34: =IF(ISBLANK('Fishing Trip'!A37)=TRUE, 'Fishing Trip'!M37, "") -> 0 | R34: =IF(ISBLANK('Fishing Operation'!A38)=TRUE, 'Fishing Operation'!F38, "") -> FOmetier5 | S34: =IF(ISBLANK('Fishing Operation'!A38)=TRUE, 'Fishing Operation'!M38, "") -> Level 5 metier | V34: =IF(ISBLANK(#REF!)=TRUE,#REF!, "") | W34: =IF(ISBLANK(#REF!)=TRUE,#REF!, "")
I35: =IF(ISBLANK(Location!#REF!)=TRUE, Location!#REF!, "") | J35: =IF(ISBLANK('Temporal Event'!A10)=TRUE, 'Temporal Event'!F10, "") -> TEstratumName | K35: =IF(ISBLANK('Temporal Event'!A10)=TRUE, 'Temporal Event'!M10, "") -> Name of stratum ('U' for unstratified) | Q35: =IF(ISBLANK('Fishing Operation'!A38)=TRUE, 'Fishing Operation'!B38, "") -> 0 | R35: =IF(ISBLANK('Fishing Operation'!A39)=TRUE, 'Fishing Operation'!F39, "") -> FOmetier6 | S35: =IF(ISBLANK('Fishing Operation'!A39)=TRUE, 'Fishing Operation'!M39, "") -> Level 6 metier | U35: =IF(ISBLANK(#REF!)=TRUE,#REF!, "") | V35: =IF(ISBLANK(#REF!)=TRUE,#REF!, "") | W35: =IF(ISBLANK(#REF!)=TRUE,#REF!, "") | Y35: =IF(ISBLANK(Sample!A43)=TRUE, Sample!B43, "") -> 0 | Z35: =IF(ISBLANK(Sample!A57)=TRUE, Sample!F57, "") -> SAauxiliaryVariableValue | AA35: =IF(ISBLANK(Sample!A57)=TRUE, Sample!M57, "") -> The value of auxiliary variable in the sampled unit.
I36: =IF(ISBLANK(Location!A10)=TRUE, Location!B10, "") -> 0 | J36: =IF(ISBLANK('Temporal Event'!A11)=TRUE, 'Temporal Event'!F11, "") -> TEclustering | K36: =IF(ISBLANK('Temporal Event'!A11)=TRUE, 'Temporal Event'!M11, "") -> Indicator existence and type of cluster sampling of units in that level of the sampling hierarchy | N36: Onshore Event (OS) | Q36: =IF(ISBLANK('Fishing Operation'!A39)=TRUE, 'Fishing Operation'!B39, "") -> 0 | R36: =IF(ISBLANK('Fishing Operation'!A40)=TRUE, 'Fishing Operation'!F40, "") -> FOgear | S36: =IF(ISBLANK('Fishing Operation'!A40)=TRUE, 'Fishing Operation'!M40, "") -> FAO Code of gear | U36: =IF(ISBLANK(#REF!)=TRUE,#REF!, "") | V36: =IF(ISBLANK(#REF!)=TRUE,#REF!, "") | W36: =IF(ISBLANK(#REF!)=TRUE,#REF!, "") | Y36: =IF(ISBLANK(Sample!#REF!)=TRUE, Sample!#REF!, "") | Z36: =IF(ISBLANK(Sample!A65)=TRUE, Sample!F58, "") -> SAauxiliaryVariableName | AA36: =IF(ISBLANK(Sample!A65)=TRUE, Sample!M58, "") -> Name of the auxiliary variable
I37: =IF(ISBLANK(Location!A14)=TRUE, Location!B14, "") -> 0 | J37: =IF(ISBLANK('Temporal Event'!A12)=TRUE, 'Temporal Event'!F12, "") -> TEclusterName | K37: =IF(ISBLANK('Temporal Event'!A12)=TRUE, 'Temporal Event'!M12, "") -> Name or code of the cluster selected for sampling | N37: =IF(ISBLANK('Onshore Event'!A2)=TRUE, 'Onshore Event'!F2, "") | O37: =IF(ISBLANK('Onshore Event'!A2)=TRUE, 'Onshore Event'!M2, "") | Q37: =IF(ISBLANK('Fishing Operation'!A40)=TRUE, 'Fishing Operation'!B40, "") -> 0 | R37: =IF(ISBLANK('Fishing Operation'!A43)=TRUE, 'Fishing Operation'!F43, "") -> FOmeshSize | S37: =IF(ISBLANK('Fishing Operation'!A43)=TRUE, 'Fishing Operation'!M43, "") -> Mesh size (mm). The following: LLD, LLS, LHM, LHP, LL, FPO cannot insert mesh size. | U37: =IF(ISBLANK(#REF!)=TRUE,#REF!, "") | V37: =IF(ISBLANK(#REF!)=TRUE,#REF!, "") | W37: =IF(ISBLANK(#REF!)=TRUE,#REF!, "") | Y37: =IF(ISBLANK(Sample!#REF!)=TRUE, Sample!#REF!, "")
I38: =IF(ISBLANK(Location!A15)=TRUE, Location!B15, "") -> 0 | J38: =IF(ISBLANK('Temporal Event'!A13)=TRUE, 'Temporal Event'!F13, "") -> TEsampler | K38: =IF(ISBLANK('Temporal Event'!A13)=TRUE, 'Temporal Event'!M13, "") -> Data collected by. E.g Selfsampling, Observer, Control, Imagery. In the future potential combinations of e.g. observer and EM. | N38: =IF(ISBLANK('Onshore Event'!A3)=TRUE, 'Onshore Event'!F3, "") | O38: =IF(ISBLANK('Onshore Event'!A3)=TRUE, 'Onshore Event'!M3, "") | Q38: =IF(ISBLANK('Fishing Operation'!A43)=TRUE, 'Fishing Operation'!B43, "") -> 0 | R38: =IF(ISBLANK('Fishing Operation'!A44)=TRUE, 'Fishing Operation'!F44, "") -> FOselectionDevice | S38: =IF(ISBLANK('Fishing Operation'!A44)=TRUE, 'Fishing Operation'!M44, "") -> Selection device. Note: this is different from IncidentalByCatchMitigateDevices. | U38: =IF(ISBLANK('Sampling Details'!A5)=TRUE, 'Sampling Details'!B5, "") -> 0 | V38: =IF(ISBLANK(#REF!)=TRUE,#REF!, "") | W38: =IF(ISBLANK(#REF!)=TRUE,#REF!, "") | Y38: =IF(ISBLANK(Sample!A45)=TRUE, Sample!B45, "") -> 0
I39: =IF(ISBLANK(Location!#REF!)=TRUE, Location!#REF!, "") | J39: =IF(ISBLANK('Temporal Event'!A14)=TRUE, 'Temporal Event'!F14, "") -> TEnumberTotal | K39: =IF(ISBLANK('Temporal Event'!A14)=TRUE, 'Temporal Event'!M14, "") -> Total number of unique time units in this stratum/cluster. | N39: =IF(ISBLANK('Onshore Event'!A4)=TRUE, 'Onshore Event'!F4, "") -> OSrecordType | O39: =IF(ISBLANK('Onshore Event'!A4)=TRUE, 'Onshore Event'!M4, "") -> Fixed value ('OS') | Q39: =IF(ISBLANK('Fishing Operation'!A44)=TRUE, 'Fishing Operation'!B44, "") -> 0 | R39: =IF(ISBLANK('Fishing Operation'!A45)=TRUE, 'Fishing Operation'!F45, "") -> FOselectionDeviceMeshSize | S39: =IF(ISBLANK('Fishing Operation'!A45)=TRUE, 'Fishing Operation'!M45, "") -> Selection device mesh size (mm) | V39: =IF(ISBLANK(#REF!)=TRUE,#REF!, "") | W39: =IF(ISBLANK(#REF!)=TRUE,#REF!, "") | Y39: =IF(ISBLANK(Sample!A46)=TRUE, Sample!B46, "") -> 0
I40: =IF(ISBLANK(Location!A18)=TRUE, Location!B18, "") -> 0 | J40: =IF(ISBLANK('Temporal Event'!A15)=TRUE, 'Temporal Event'!F15, "") -> TEnumberSampled | K40: =IF(ISBLANK('Temporal Event'!A15)=TRUE, 'Temporal Event'!M15, "") -> The number of time units sampled in this stratum/cluster (not necessarily unique time units, the same time unit could be sampled more than once) . If 3 samples was made and one time unit was selected twice, the number of time units sampled is 3. | N40: =IF(ISBLANK('Onshore Event'!#REF!)=TRUE, 'Onshore Event'!#REF!, "") | O40: =IF(ISBLANK('Onshore Event'!A6)=TRUE, 'Onshore Event'!M6, "") -> Indicator of presence ("Y") or absence ("N") of stratification of units in that level of the sampling hierarchy | Q40: =IF(ISBLANK('Fishing Operation'!A45)=TRUE, 'Fishing Operation'!B45, "") -> 0 | R40: =IF(ISBLANK('Fishing Operation'!A46)=TRUE, 'Fishing Operation'!F46, "") -> FOtargetSpecies | S40: =IF(ISBLANK('Fishing Operation'!A46)=TRUE, 'Fishing Operation'!M46, "") -> Target species assemblage | V40: =IF(ISBLANK(#REF!)=TRUE,#REF!, "") | W40: =IF(ISBLANK(#REF!)=TRUE,#REF!, "") | Y40: =IF(ISBLANK(Sample!A50)=TRUE, Sample!B50, "") -> 0
I41: =IF(ISBLANK(Location!A27)=TRUE, Location!B27, "") -> 0 | J41: =IF(ISBLANK('Temporal Event'!#REF!)=TRUE, 'Temporal Event'!#REF!, "") | K41: =IF(ISBLANK('Temporal Event'!#REF!)=TRUE, 'Temporal Event'!#REF!, "") | N41: =IF(ISBLANK('Onshore Event'!A6)=TRUE, 'Onshore Event'!F6, "") -> OSstratification | O41: =IF(ISBLANK('Onshore Event'!A7)=TRUE, 'Onshore Event'!M7, "") -> LOCODE of sampling location | Q41: =IF(ISBLANK('Fishing Operation'!A46)=TRUE, 'Fishing Operation'!B46, "") -> 0 | R41: =IF(ISBLANK('Fishing Operation'!A47)=TRUE, 'Fishing Operation'!F47, "") -> FOincidentalByCatchMitigationDeviceFirst | S41: =IF(ISBLANK('Fishing Operation'!A47)=TRUE, 'Fishing Operation'!M47, "") -> First mitigation device specific for reducing incidental by-catch | V41: =IF(ISBLANK(#REF!)=TRUE,#REF!, "") | W41: =IF(ISBLANK(#REF!)=TRUE,#REF!, "")
...

Sheet Design
A1: Hide | B1: PK/FK | C1: Unique combination of fields | D1: Order | E1: Field Name Description | F1: Field Name | G1: R Name | H1: Type | I1: Required | J1: Basic checks | K1: Vocabulary code type | L1: Description | M1: Short Description
A2: Y | B2: PK | D2: Not in format | E2: Design ID | F2: DEid | G2: DEid | H2: Integer | L2: Automatic ID - PK of table. Internal to RDBES. Not to be filled in by users. | M2: Automatic ID - PK of table
D3: 1 | E3: Record type | F3: DErecordType | G3: DErecType | H3: String | I3: M | J3: DE | L3: Fixed value DE. | M3: Fixed value ('DE')
C4: Uk1 | D4: 2 | E4: Sampling scheme | F4: DEsamplingScheme | G4: DEsampScheme | H4: String | I4: M | J4: Code list | K4: SamplingScheme //vocab.ices.dk/?ref=1664 | L4: The name for the sampling scheme under which the data were collected. Contact support if you need your sampling scheme added | M4: Sampling Scheme Name
D5: 3 | E5: Sampling scheme type | F5: DEsamplingSchemeType | G5: DEsampSchemeType | H5: String | I5: M | J5: Code list | K5: SamplingSchemeType //vocab.ices.dk/?ref=1665 | L5: Indicating the sampling scheme type code list: 'Regional Routine', 'Regional Pilot', 'National Routine', 'National Pilot' or 'Research project'. Routine is continued maybe with updates each year. A pilot is a test of a routine so it is done for the first time for a short periode. Research is all other studies/projects. | M5: Sampling scheme type code list: 'Regional Routine', 'Regional Pilot', 'National Routine', 'National Pilot'.
C6: Uk1 | D6: 4 | E6: Year | F6: DEyear | G6: DEyear | H6: Integer | I6: M | J6: Code list | K6: Year //vocab.ices.dk/?ref=362 | L6: Year when sampling was done | M6: Year of sampling
C7: Uk1 | D7: 5 | E7: Design stratum | F7: DEstratumName | G7: DEstratumName | H7: String(100) | I7: M | L7: This is the sampling frame stratum. The field is kept here, because you could have different hierarchies between strata in a sampling scheme eg. a regional scheme. The name of the stratum, all strata should have a record in this table, one record per stratum. | M7: Sampling frame stratum.
D8: 6 | E8: Hierarchy correct | F8: DEhierarchyCorrect | G8: DEhierarchyCor | H8: String | I8: M | J8: Code list | K8: YesNoFields //vocab.ices.dk/?ref=316 | L8: Yes or No. "Yes", if you clearly idetified the hierarchy and estimates can be made following the design. "No", if the hierarchy was difficult to determine. | M8: Was the hierarchy clearly identified?
D9: 7 | E9: Hierarchy | F9: DEhierarchy | G9: DEhierarchy | H9: Integer | I9: M | J9: Code list | K9: RDBESUpperHierarchy //vocab.ices.dk/?ref=1627 | L9: A code refering to the upper hierarchy that the data was collected using (see documentation for explanation). | M9: Upper Hierarchy
D10: 8 | E10: Sampled | F10: DEsampled | G10: DEsamp | H10: String | I10: DV, M | J10: Code list | K10: YesNoFields //vocab.ices.dk/?ref=316 | L10: Indicate if the stratum was sampled: Yes/No. If "No" then no records are expected after the "Sampling Details" record.
D11: 9 | E11: Reason for not sampling | F11: DEreasonNotSampled | G11: DEnoSampReason | H11: String | I11: DV, O | J11: Code list | K11: ReasonForNotSampling //vocab.ices.dk/?ref=1641 | L11: Reason for not sampling | M11: Reason for not sampling
D12: 10 | E12: Non-response collected at this level | F12: DEnonResponseCollected | G12: DEnonResponseCollected | H12: String | I12: DV,O | J12: Code list | K12: YesNoFields //vocab.ices.dk/?ref=316 | L12: Indicate whether non-responses were recorded at this sampling level. | M12: Indicate whether non-responses were recorded at this sampling level.
D13: 11 | E13: Auxiliary Variable Total | F13: DEauxiliaryVariableTotal | G13: DEauxVarTot | H13: Decimal(3) | I13: DV, O | L13: The total value of auxiliary variable in the stratum (to be used in, e.g., ratio estimation). Auxiliary variables are 'extra' variables measured in association with the desired variable that might be used to increase precision of the estimate. | M13: The total value of auxiliary variable in the stratum
